Workbook

Sheet Daily
A1: Habit | B1: Monday | C1: Tuesday | D1: Wednesday | E1: Thursday | F1: Friday | G1: Saturday | H1: Sunday | I1: Weekly Total | J1: Progress % | K1: All Done? | L1: Emoji
A3: Wake up early | B3: TRUE | C3: TRUE | D3: TRUE | E3: TRUE | F3: FALSE | G3: FALSE | H3: FALSE | I3: =COUNTIF(B3:H3, TRUE) -> 4 | J3: =I3/7 -> 0.57142857 | K3: =AND(B3:H3) -> FALSE | L3: =IF(K3=TRUE,"🔥","😴") -> 😴
A4: Meditation 5 minutes | B4: FALSE | C4: TRUE | D4: TRUE | E4: TRUE | F4: FALSE | G4: FALSE | H4: FALSE | I4: =COUNTIF(B4:H4, TRUE) -> 3 | J4: =I4/7 -> 0.42857143 | K4: =AND(B4:H4) -> FALSE | L4: =IF(K4=TRUE,"🔥","😴") -> 😴
A5: Ice Cube Face Wash | B5: FALSE | C5: TRUE | D5: FALSE | E5: TRUE | F5: FALSE | G5: FALSE | H5: FALSE | I5: =COUNTIF(B5:H5, TRUE) -> 2 | J5: =I5/7 -> 0.28571429 | K5: =AND(B5:H5) -> FALSE | L5: =IF(K5=TRUE,"🔥","😴") -> 😴
A6: Prepare your day / planning | B6: TRUE | C6: TRUE | D6: TRUE | E6: TRUE | F6: FALSE | G6: FALSE | H6: FALSE | I6: =COUNTIF(B6:H6, TRUE) -> 4 | J6: =I6/7 -> 0.57142857 | K6: =AND(B6:H6) -> FALSE | L6: =IF(K6=TRUE,"🔥","😴") -> 😴
A7: Workout | B7: TRUE | C7: TRUE | D7: TRUE | E7: TRUE | F7: FALSE | G7: FALSE | H7: FALSE | I7: =COUNTIF(B7:H7, TRUE) -> 4 | J7: =I7/7 -> 0.57142857 | K7: =AND(B7:H7) -> FALSE | L7: =IF(K7=TRUE,"🔥","😴") -> 😴
A8: Meal 1 (breakfast) | B8: TRUE | C8: TRUE | D8: TRUE | E8: TRUE | F8: FALSE | G8: FALSE | H8: FALSE | I8: =COUNTIF(B8:H8, TRUE) -> 4 | J8: =I8/7 -> 0.57142857 | K8: =AND(B8:H8) -> FALSE | L8: =IF(K8=TRUE,"🔥","😴") -> 😴
A9: Bath 1 | B9: FALSE | C9: TRUE | D9: FALSE | E9: FALSE | F9: FALSE | G9: FALSE | H9: FALSE | I9: =COUNTIF(B9:H9, TRUE) -> 1 | J9: =I9/7 -> 0.14285714 | K9: =AND(B9:H9) -> FALSE | L9: =IF(K9=TRUE,"🔥","😴") -> 😴
A10: Dress well | B10: TRUE | C10: TRUE | D10: TRUE | E10: TRUE | F10: FALSE | G10: FALSE | H10: FALSE | I10: =COUNTIF(B10:H10, TRUE) -> 4 | J10: =I10/7 -> 0.57142857 | K10: =AND(B10:H10) -> FALSE | L10: =IF(K10=TRUE,"🔥","😴") -> 😴
A11: Go to college | B11: FALSE | C11: FALSE | D11: FALSE | E11: FALSE | F11: FALSE | G11: FALSE | H11: FALSE | I11: =COUNTIF(B11:H11, TRUE) -> 0 | J11: =I11/7 -> 0 | K11: =AND(B11:H11) -> FALSE | L11: =IF(K11=TRUE,"🔥","😴") -> 😴
A12: Meal 2 (lunch) | B12: TRUE | C12: TRUE | D12: TRUE | E12: TRUE | F12: FALSE | G12: FALSE | H12: FALSE | I12: =COUNTIF(B12:H12, TRUE) -> 4 | J12: =I12/7 -> 0.57142857 | K12: =AND(B12:H12) -> FALSE | L12: =IF(K12=TRUE,"🔥","😴") -> 😴
A13: Meal 3 (snack) | B13: TRUE | C13: TRUE | D13: TRUE | E13: TRUE | F13: FALSE | G13: FALSE | H13: FALSE | I13: =COUNTIF(B13:H13, TRUE) -> 4 | J13: =I13/7 -> 0.57142857 | K13: =AND(B13:H13) -> FALSE | L13: =IF(K13=TRUE,"🔥","😴") -> 😴
A14: Spend Time With Friends | B14: FALSE | C14: FALSE | D14: TRUE | E14: FALSE | F14: FALSE | G14: FALSE | H14: FALSE | I14: =COUNTIF(B14:H14, TRUE) -> 1 | J14: =I14/7 -> 0.14285714 | K14: =AND(B14:H14) -> FALSE | L14: =IF(K14=TRUE,"🔥","😴") -> 😴
... A30: Sleep 6-8hr | B30: TRUE | C30: TRUE | D30: TRUE | E30: TRUE | F30: FALSE | G30: FALSE | H30: FALSE | I30: =COUNTIF(B30:H30, TRUE) -> 4 | J30: =I30/7 -> 0.57142857 | K30: =AND(B30:H30) -> FALSE | L30: =IF(K30=TRUE,"🔥","😴") -> 😴
A32: All Done? | B32: =AND(B3:B19) -> FALSE | C32: =AND(C3:C19) -> FALSE | D32: =AND(D3:D19) -> FALSE | E32: =AND(E3:E19) -> FALSE | F32: =AND(F3:F19) -> FALSE | G32: =AND(F3:F19) -> FALSE | H32: =AND(H3:H19) -> FALSE
A33: Emoji | B33: =IF(B32=TRUE,"🔥","😴") -> 😴 | C33: =IF(C32=TRUE,"🔥","😴") -> 😴 | D33: =IF(D32=TRUE,"🔥","😴") -> 😴 | E33: =IF(E32=TRUE,"🔥","😴") -> 😴 | F33: =IF(F32=TRUE,"🔥","😴") -> 😴 | G33: =IF(G32=TRUE,"🔥","😴") -> 😴 | H33: =IF(H32=TRUE,"🔥","😴") -> 😴
K34: Flase=not a perfect day
K35: True=you completed all habits that day
A40: Overall Progress
G43: Monday | H43: Tuesday | I43: Wednesday | J43: Thursday | K43: Friday | L43: Saturday | M43: Sunday
F44: Completed % | G44: =COUNTIF(Daily!B$3:B$30, TRUE) / COUNTA(Daily!B$3:B$30) -> 0.5 | H44: =COUNTIF(Daily!C$3:C$30, TRUE) / COUNTA(Daily!C$3:C$30) -> 0.67857143 | I44: =COUNTIF(Daily!D$3:D$30, TRUE) / COUNTA(Daily!D$3:D$30) -> 0.67857143 | J44: =COUNTIF(Daily!E$3:E$30, TRUE) / COUNTA(Daily!E$3:E$30) -> 0.60714286 | K44: =COUNTIF(Daily!F$3:F$30, TRUE) / COUNTA(Daily!F$3:F$30) -> 0 | L44: =COUNTIF(Daily!G$3:G$30, TRUE) / COUNTA(Daily!G$3:G$30) -> 0 | M44: =COUNTIF(Daily!H$3:H$30, TRUE) / COUNTA(Daily!H$3:H$30) -> 0
F45: Remining % | G45: =1-G44 -> 0.5 | H45: =1-H44 -> 0.32142857 | I45: =1-I44 -> 0.32142857 | J45: =1-J44 -> 0.39285714 | K45: =1-K44 -> 1 | L45: =1-L44 -> 1 | M45: =1-M44 -> 1
F47: Average of C% | G47: =AVERAGE(G44:M44) -> 0.35204082
F48: Average of R% | G48: =AVERAGE(G45:M45) -> 0.64795918

Sheet Every Date
A1: Year | B1: Months | C1: Dates | D1: Days | E1: Complete Habits | F1: Total Habits | G1: Remining Habits | H1: Daily Progress % | I1: Daily Score Out of 10
A2: 2025 | B2: December | C2: {=SEQUENCE(31,1,DATE(2025,12,1),1)} -> 45992 | D2: Monday | E2: 16 | F2: 28 | G2: =(F2-E2) -> 12 | H2: =E2/F2 -> 0.57142857 | I2: =ROUND((E2/F2)*10,1) -> 5.7 | J2: Highest Progress | K2: =MAX(H2:H32) -> 0.67857143
C3: 45993 | D3: Tuesday | E3: 12 | F3: 28 | G3: =(F3-E3) -> 16 | H3: =E3/F3 -> 0.42857143 | I3: =ROUND((E3/F3)*10,1) -> 4.3
C4: 45994 | D4: Wednesday | E4: 10 | F4: 28 | G4: =(F4-E4) -> 18 | H4: =E4/F4 -> 0.35714286 | I4: =ROUND((E4/F4)*10,1) -> 3.6 | J4: Lowest Progress | K4: =MIN(H2:H32) -> 0
C5: 45995 | D5: Thursday | E5: 13 | F5: 28 | G5: =(F5-E5) -> 15 | H5: =E5/F5 -> 0.46428571 | I5: =ROUND((E5/F5)*10,1) -> 4.6
C6: 45996 | D6: Friday | E6: 14 | F6: 28 | G6: =(F6-E6) -> 14 | H6: =E6/F6 -> 0.5 | I6: =ROUND((E6/F6)*10,1) -> 5 | J6: Average Progress | K6: =AVERAGE(H2:H32) -> 0.17626728
C7: 45997 | D7: Saturday | E7: 19 | F7: 28 | G7: =(F7-E7) -> 9 | H7: =E7/F7 -> 0.67857143 | I7: =ROUND((E7/F7)*10,1) -> 6.8
C8: 45998 | D8: Sunday | E8: 16 | F8: 28 | G8: =(F8-E8) -> 12 | H8: =E8/F8 -> 0.57142857 | I8: =ROUND((E8/F8)*10,1) -> 5.7
C9: 45999 | D9: Monday | E9: 15 | F9: 28 | G9: =(F9-E9) -> 13 | H9: =E9/F9 -> 0.53571429 | I9: =ROUND((E9/F9)*10,1) -> 5.4
C10: 46000 | D10: Tuesday | E10: 19 | F10: 28 | G10: =(F10-E10) -> 9 | H10: =E10/F10 -> 0.67857143 | I10: =ROUND((E10/F10)*10,1) -> 6.8
C11: 46001 | D11: Wednesday | E11: 19 | F11: 28 | G11: =(F11-E11) -> 9 | H11: =E11/F11 -> 0.67857143 | I11: =ROUND((E11/F11)*10,1) -> 6.8
C12: 46002 | D12: Thursday | F12: 28 | G12: =(F12-E12) -> 28 | H12: =E12/F12 -> 0 | I12: =ROUND((E12/F12)*10,1) -> 0
C13: 46003 | D13: Friday | F13: 28 | G13: =(F13-E13) -> 28 | H13: =E13/F13 -> 0 | I13: =ROUND((E13/F13)*10,1) -> 0
C14: 46004 | D14: Saturday | F14: 28 | G14: =(F14-E14) -> 28 | H14: =E14/F14 -> 0 | I14: =ROUND((E14/F14)*10,1) -> 0
C15: 46005 | D15: Sunday | F15: 28 | G15: =(F15-E15) -> 28 | H15: =E15/F15 -> 0 | I15: =ROUND((E15/F15)*10,1) -> 0
C16: 46006 | D16: Monday | F16: 28 | G16: =(F16-E16) -> 28 | H16: =E16/F16 -> 0 | I16: =ROUND((E16/F16)*10,1) -> 0
C17: 46007 | D17: Tuesday | F17: 28 | G17: =(F17-E17) -> 28 | H17: =E17/F17 -> 0 | I17: =ROUND((E17/F17)*10,1) -> 0
C18: 46008 | D18: Wednesday | F18: 28 | G18: =(F18-E18) -> 28 | H18: =E18/F18 -> 0 | I18: =ROUND((E18/F18)*10,1) -> 0
C19: 46009 | D19: Thursday | F19: 28 | G19: =(F19-E19) -> 28 | H19: =E19/F19 -> 0 | I19: =ROUND((E19/F19)*10,1) -> 0
C20: 46010 | D20: Friday | F20: 28 | G20: =(F20-E20) -> 28 | H20: =E20/F20 -> 0 | I20: =ROUND((E20/F20)*10,1) -> 0
C21: 46011 | D21: Saturday | F21: 28 | G21: =(F21-E21) -> 28 | H21: =E21/F21 -> 0 | I21: =ROUND((E21/F21)*10,1) -> 0
C22: 46012 | D22: Sunday | F22: 28 | G22: =(F22-E22) -> 28 | H22: =E22/F22 -> 0 | I22: =ROUND((E22/F22)*10,1) -> 0
C23: 46013 | D23: Monday | F23: 28 | G23: =(F23-E23) -> 28 | H23: =E23/F23 -> 0 | I23: =ROUND((E23/F23)*10,1) -> 0
... C32: 46022 | D32: Wednesday | F32: 28 | G32: =(F32-E32) -> 28 | H32: =E32/F32 -> 0 | I32: =ROUND((E32/F32)*10,1) -> 0
A34: 2026 | B34: January | C34: {=SEQUENCE(31,1,DATE(2026,1,1),1)} -> 46023 | D34: Thursday | E34: 0 | F34: 0 | G34: =(F34-E34) -> 0 | H34: =E34/F34 -> #DIV/0! | I34: =ROUND((E34/F34)*10,1) -> #DIV/0! | J34: Highest Progress | K34: =MAX(H34:H64) -> #DIV/0!
C35: 46024 | D35: Friday | E35: 0 | F35: 0 | G35: =(F35-E35) -> 0 | H35: =E35/F35 -> #DIV/0! | I35: =ROUND((E35/F35)*10,1) -> #DIV/0!
C36: 46025 | D36: Saturday | E36: 0 | F36: 0 | G36: =(F36-E36) -> 0 | H36: =E36/F36 -> #DIV/0! | I36: =ROUND((E36/F36)*10,1) -> #DIV/0! | J36: Lowest Progress | K36: =MIN(H34:H64) -> #DIV/0!
C37: 46026 | D37: Sunday | E37: 0 | F37: 0 | G37: =(F37-E37) -> 0 | H37: =E37/F37 -> #DIV/0! | I37: =ROUND((E37/F37)*10,1) -> #DIV/0!
C38: 46027 | D38: Monday | E38: 0 | F38: 0 | G38: =(F38-E38) -> 0 | H38: =E38/F38 -> #DIV/0! | I38: =ROUND((E38/F38)*10,1) -> #DIV/0! | J38: Average Progress | K38: =AVERAGE(H34:H64) -> #DIV/0!
C39: 46028 | D39: Tuesday | E39: 0 | F39: 0 | G39: =(F39-E39) -> 0 | H39: =E39/F39 -> #DIV/0! | I39: =ROUND((E39/F39)*10,1) -> #DIV/0!
C40: 46029 | D40: Wednesday | E40: 0 | F40: 0 | G40: =(F40-E40) -> 0 | H40: =E40/F40 -> #DIV/0! | I40: =ROUND((E40/F40)*10,1) -> #DIV/0!
C41: 46030 | D41: Thursday | E41: 0 | F41: 0 | G41: =(F41-E41) -> 0 | H41: =E41/F41 -> #DIV/0! | I41: =ROUND((E41/F41)*10,1) -> #DIV/0!
C42: 46031 | D42: Friday | E42: 0 | F42: 0 | G42: =(F42-E42) -> 0 | H42: =E42/F42 -> #DIV/0! | I42: =ROUND((E42/F42)*10,1) -> #DIV/0!
C43: 46032 | D43: Saturday | E43: 0 | F43: 0 | G43: =(F43-E43) -> 0 | H43: =E43/F43 -> #DIV/0! | I43: =ROUND((E43/F43)*10,1) -> #DIV/0!
C44: 46033 | D44: Sunday | E44: 0 | F44: 0 | G44: =(F44-E44) -> 0 | H44: =E44/F44 -> #DIV/0! | I44: =ROUND((E44/F44)*10,1) -> #DIV/0!
C45: 46034 | D45: Monday | E45: 0 | F45: 0 | G45: =(F45-E45) -> 0 | H45: =E45/F45 -> #DIV/0! | I45: =ROUND((E45/F45)*10,1) -> #DIV/0!
C46: 46035 | D46: Tuesday | E46: 0 | F46: 0 | G46: =(F46-E46) -> 0 | H46: =E46/F46 -> #DIV/0! | I46: =ROUND((E46/F46)*10,1) -> #DIV/0!
C47: 46036 | D47: Wednesday | E47: 0 | F47: 0 | G47: =(F47-E47) -> 0 | H47: =E47/F47 -> #DIV/0! | I47: =ROUND((E47/F47)*10,1) -> #DIV/0!
C48: 46037 | D48: Thursday | E48: 0 | F48: 0 | G48: =(F48-E48) -> 0 | H48: =E48/F48 -> #DIV/0! | I48: =ROUND((E48/F48)*10,1) -> #DIV/0!
C49: 46038 | D49: Friday | E49: 0 | F49: 0 | G49: =(F49-E49) -> 0 | H49: =E49/F49 -> #DIV/0! | I49: =ROUND((E49/F49)*10,1) -> #DIV/0!
...

Sheet Weekly
B1: Week | D1: Completed % | F1: Remaining %
B3: Week 5 | D3: 0 | F3: =1-D3 -> 1
B5: Week 4 | D5: 0 | F5: =1-D5 -> 1
B7: Week 3 | D7: 0 | F7: =1-D7 -> 1
B9: Week 2 | D9: 0.82 | F9: =1-D9 -> 0.18
B11: Week 1 | D11: 0.5102 | F11: 0.4898
I22: ⭐ Best Week | J22: =MAX(D3:D11) -> 0.82
I24: 😢 Worst Week | J24: =MIN(D3:D11) -> 0
I26: 📊 Average | J26: =AVERAGE(D3:D11) -> 0.26604
I28: 📈 Trend | J28: =IF(D3>D11,"Improving","Declining") -> Declining

Sheet Monthly
A1: Months | B1: Year | C1: Week 1 % | D1: Week 2 % | E1: Week 3 % | F1: Week 4 % | G1: Week 5% | H1: Overall % | I1: Remining % | J1: Best Week | K1: Worst Week | L1: Insights | M1: Monthly Rank
A3: December | B3: 2025 | C3: 0.5102 | D3: 0.82 | E3: 0 | F3: 0 | G3: 0 | H3: =AVERAGE(C3:G3) -> 0.26604 | I3: =1-H3 -> 0.73396 | J3: =MAX(C3:G3) -> 0.82 | K3: =MIN(C3:F3) -> 0 | L3: =IF(H3="", "",IF(H3>=0.75, "Excellent Month 🎉",IF(H3>=0.6, "Good Progress 🙂", IF(H3>=0.4, "Average – Can Improve ⚠️","Needs Attention ❌")))) -> Needs Attention ❌ | M3: =IF(H3="","", RANK(H3, $H$3:$H$27, 0)) -> 1
D4: =IF(A4="","", WEEKDAY(A4))
A5: January | B5: 2026 | C5: 0 | D5: 0 | E5: 0 | F5: 0 | G5: 0 | H5: =AVERAGE(C5:G5) -> 0 | I5: =1-H5 -> 1 | J5: =MAX(C5:G5) -> 0 | K5: =MIN(C5:F5) -> 0 | L5: "Needs Attention ❌" | M5: =IF(H5="","", RANK(H5, $H$3:$H$27, 0)) -> 2
D6: =IF(A6="","", WEEKDAY(A6))
A7: February | B7: 2026 | C7: 0 | D7: 0 | E7: 0 | F7: 0 | G7: 0 | H7: =AVERAGE(C7:G7) -> 0 | I7: =1-H7 -> 1 | J7: =MAX(C7:G7) -> 0 | K7: 0 | L7: =IF(H7="", "",IF(H7>=0.75, "Excellent Month 🎉",IF(H7>=0.6, "Good Progress 🙂", IF(H7>=0.4, "Average – Can Improve ⚠️","Needs Attention ❌")))) -> Needs Attention ❌ | M7: =IF(H7="","", RANK(H7, $H$3:$H$27, 0)) -> 2
D8: =IF(A8="","", WEEKDAY(A8))
A9: March | B9: 2026 | C9: 0 | D9: 0 | E9: 0 | F9: 0 | G9: 0 | H9: =AVERAGE(C9:G9) -> 0 | I9: =1-H9 -> 1 | J9: =MAX(C9:G9) -> 0 | K9: 0 | L9: =IF(H9="", "",IF(H9>=0.75, "Excellent Month 🎉",IF(H9>=0.6, "Good Progress 🙂", IF(H9>=0.4, "Average – Can Improve ⚠️","Needs Attention ❌")))) -> Needs Attention ❌ | M9: =IF(H9="","", RANK(H9, $H$3:$H$27, 0)) -> 2
D10: =IF(A10="","", WEEKDAY(A10))
A11: April | B11: 2026 | C11: 0 | D11: 0 | E11: 0 | F11: 0 | G11: 0 | H11: =AVERAGE(C11:G11) -> 0 | I11: =1-H11 -> 1 | J11: 0 | K11: 0 | L11: =IF(H11="", "",IF(H11>=0.75, "Excellent Month 🎉",IF(H11>=0.6, "Good Progress 🙂", IF(H11>=0.4, "Average – Can Improve ⚠️","Needs Attention ❌")))) -> Needs Attention ❌ | M11: =IF(H11="","", RANK(H11, $H$3:$H$27, 0)) -> 2
D12: =IF(A12="","", WEEKDAY(A12))
A13: May | B13: 2026 | C13: 0 | D13: 0 | E13: 0 | F13: 0 | G13: 0 | H13: =AVERAGE(C13:G13) -> 0 | I13: =1-H13 -> 1 | J13: 0 | K13: 0 | L13: =IF(H13="", "",IF(H13>=0.75, "Excellent Month 🎉",IF(H13>=0.6, "Good Progress 🙂", IF(H13>=0.4, "Average – Can Improve ⚠️","Needs Attention ❌")))) -> Needs Attention ❌ | M13: =IF(H13="","", RANK(H13, $H$3:$H$27, 0)) -> 2
A15: June | B15: 2026 | C15: 0 | D15: 0 | E15: 0 | F15: 0 | G15: 0 | H15: =AVERAGE(C15:G15) -> 0 | I15: =1-H15 -> 1 | J15: 0 | K15: 0 | L15: =IF(H15="", "",IF(H15>=0.75, "Excellent Month 🎉",IF(H15>=0.6, "Good Progress 🙂", IF(H15>=0.4, "Average – Can Improve ⚠️","Needs Attention ❌")))) -> Needs Attention ❌ | M15: =IF(H15="","", RANK(H15, $H$3:$H$27, 0)) -> 2
A17: July | B17: 2026 | C17: 0 | D17: 0 | E17: 0 | F17: 0 | G17: 0 | H17: =AVERAGE(C17:G17) -> 0 | I17: =1-H17 -> 1 | J17: 0 | K17: 0 | L17: =IF(H17="", "",IF(H17>=0.75, "Excellent Month 🎉",IF(H17>=0.6, "Good Progress 🙂", IF(H17>=0.4, "Average – Can Improve ⚠️","Needs Attention ❌")))) -> Needs Attention ❌ | M17: =IF(H17="","", RANK(H17, $H$3:$H$27, 0)) -> 2
A19: August | B19: 2026 | C19: 0 | D19: 0 | E19: 0 | F19: 0 | G19: 0 | H19: =AVERAGE(C19:G19) -> 0 | I19: =1-H19 -> 1 | J19: 0 | K19: 0 | L19: =IF(H19="", "",IF(H19>=0.75, "Excellent Month 🎉",IF(H19>=0.6, "Good Progress 🙂", IF(H19>=0.4, "Average – Can Improve ⚠️","Needs Attention ❌")))) -> Needs Attention ❌ | M19: =IF(H19="","", RANK(H19, $H$3:$H$27, 0)) -> 2
A21: September | B21: 2026 | C21: 0 | D21: 0 | E21: 0 | F21: 0 | G21: 0 | H21: =AVERAGE(C21:G21) -> 0 | I21: =1-H21 -> 1 | J21: 0 | K21: 0 | L21: =IF(H21="", "",IF(H21>=0.75, "Excellent Month 🎉",IF(H21>=0.6, "Good Progress 🙂", IF(H21>=0.4, "Average – Can Improve ⚠️","Needs Attention ❌")))) -> Needs Attention ❌ | M21: =IF(H21="","", RANK(H21, $H$3:$H$27, 0)) -> 2
A23: October | B23: 2026 | C23: 0 | D23: 0 | E23: 0 | F23: 0 | G23: 0 | H23: =AVERAGE(C23:G23) -> 0 | I23: =1-H23 -> 1 | J23: 0 | K23: 0 | L23: =IF(H23="", "",IF(H23>=0.75, "Excellent Month 🎉",IF(H23>=0.6, "Good Progress 🙂", IF(H23>=0.4, "Average – Can Improve ⚠️","Needs Attention ❌")))) -> Needs Attention ❌ | M23: =IF(H23="","", RANK(H23, $H$3:$H$27, 0)) -> 2
A25: November | B25: 2026 | C25: 0 | D25: 0 | E25: 0 | F25: 0 | G25: 0 | H25: =AVERAGE(C25:G25) -> 0 | I25: =1-H25 -> 1 | J25: 0 | K25: 0 | L25: =IF(H25="", "",IF(H25>=0.75, "Excellent Month 🎉",IF(H25>=0.6, "Good Progress 🙂", IF(H25>=0.4, "Average – Can Improve ⚠️","Needs Attention ❌")))) -> Needs Attention ❌ | M25: =IF(H25="","", RANK(H25, $H$3:$H$27, 0)) -> 2
A27: December | B27: 2026 | C27: 0 | D27: 0 | E27: 0 | F27: 0 | G27: 0 | H27: =AVERAGE(C27:G27) -> 0 | I27: =1-H27 -> 1 | J27: 0 | K27: 0 | L27: =IF(H27="", "",IF(H27>=0.75, "Excellent Month 🎉",IF(H27>=0.6, "Good Progress 🙂", IF(H27>=0.4, "Average – Can Improve ⚠️","Needs Attention ❌")))) -> Needs Attention ❌ | M27: =IF(H27="","", RANK(H27, $H$3:$H$27, 0)) -> 2
D28: =IF(A28="","", WEEKDAY(A28))
D29: =IF(A29="","", WEEKDAY(A29))
D31: =IF(A31="","", WEEKDAY(A31))
D32: =IF(A32="","", WEEKDAY(A32))
D33: =IF(A33="","", WEEKDAY(A33))
D34: =IF(A34="","", WEEKDAY(A34))
D35: =IF(A35="","", WEEKDAY(A35))
D36: =IF(A36="","", WEEKDAY(A36))
D37: =IF(A37="","", WEEKDAY(A37))
D38: =IF(A38="","", WEEKDAY(A38))
D39: =IF(A39="","", WEEKDAY(A39))
D40: =IF(A40="","", WEEKDAY(A40))
... D385: =IF(A385="","", WEEKDAY(A385))

Sheet Things
A2: ----] One Of The Important Year In Your Life----🧑
